<robot xmlns:xacro="http://ros.org/wiki/xacro">
	<xacro:macro name="NM45_mesh" params="prefix">
		<!-- link list -->
		<link name="${prefix}base_link">
			<visual>
				<geometry>
					<mesh filename="package://comau_config/meshes/visual/NM-45_Base.STL" />
				</geometry>
				<material name="red">
					<color rgba="1 0 0 1"/>
				</material>
			</visual>
			<collision>
				<geometry>
					<mesh filename="package://comau_config/meshes/collision/NM-45_Base_CH.STL" />
				</geometry>
				<material name="yellow">
					<color rgba="0 1 1 1"/>
				</material>
			</collision>
		</link>
		<link name="${prefix}link1">
			<visual>
				<origin rpy="0 0 0" xyz="0 0 0"/>
				<geometry>
					<mesh filename="package://comau_config/meshes/visual/NM-45_Link1.STL"/>
				</geometry>
				<material name="red">
					<color rgba="1 0 0 1"/>
				</material>
			</visual>
			<collision>
				<origin rpy="0 0 0" xyz="0 0 0"/>
				<geometry>
					<mesh filename="package://comau_config/meshes/collision/NM-45_Link1_CH.STL" />
				</geometry>
				<material name="yellow"/>
			</collision>
		</link>
		<link name="${prefix}link2">
			<visual>
				<origin rpy="0 0 0" xyz="0 0 0"/>
				<geometry>
					<mesh filename="package://comau_config/meshes/visual/NM-45_Link2.STL"/>
				</geometry>
				<material name="red"/>
			</visual>
			<collision>
				<origin rpy="0 0 0" xyz="0 0 0"/>
				<geometry>
					<mesh filename="package://comau_config/meshes/collision/NM-45_Link2_CH.STL"/>
				</geometry>
				<material name="yellow"/>
			</collision>
		</link>
		<link name="${prefix}link3">
			<visual>
				<origin rpy="0 0 0" xyz="0 0 0"/>
				<geometry>
					<mesh filename="package://comau_config/meshes/visual/NM-45_Link3.STL"/>
				</geometry>
				<material name="red"/>
			</visual>
			<collision>
				<origin rpy="0 0 0" xyz="0 0 0"/>
				<geometry>
					<mesh filename="package://comau_config/meshes/collision/NM-45_Link3_CH.STL"/>
				</geometry>
				<material name="yellow"/>
			</collision>
		</link>
		<link name="${prefix}link4">
			<visual>
				<origin rpy="0 0 0" xyz="0 0 0"/>
				<geometry>
					<mesh filename="package://comau_config/meshes/visual/NM-45_Link4.STL"/>
				</geometry>
				<material name="red"/>
			</visual>
			<collision>
				<origin rpy="0 0 0" xyz="0 0 0"/>
				<geometry>
					<mesh filename="package://comau_config/meshes/collision/NM-45_Link4_CH.STL"/>
				</geometry>
				<material name="yellow"/>
			</collision>
		</link>
		<link name="${prefix}link5">
			<visual>
				<origin rpy="0 0 0" xyz="0 0 0"/>
				<geometry>
					<mesh filename="package://comau_config/meshes/visual/NM-45_Link5.STL"/>
				</geometry>
				<material name="red"/>
			</visual>
			<collision>
				<origin rpy="0 0 0" xyz="0 0 0"/>
				<geometry>
					<mesh filename="package://comau_config/meshes/collision/NM-45_Link5_CH.STL"/>
				</geometry>
				<material name="yellow"/>
			</collision>
		</link>
		<link name="${prefix}link6">
			<visual>
				<origin rpy="0 0 0" xyz="0 0 0"/>
				<geometry>
					<mesh filename="package://comau_config/meshes/visual/NM-45_Link6.STL"/>
				</geometry>
				<material name="red"/>
			</visual>
			<collision>
				<origin rpy="0 0 0" xyz="0 0 0"/>
				<geometry>
					<mesh filename="package://comau_config/meshes/collision/NM-45_Link6_CH.STL"/>
				</geometry>
				<material name="yellow"/>
			</collision>
		</link>
		<!-- end of link list -->
		<!-- joint list -->
		<joint name="${prefix}joint1" type="revolute">
			<parent link="base_link"/>
			<child link="link1"/>
			<origin xyz="0 0 0.305" rpy="0 0 0"/>
			<axis xyz="0 0 -1" />
			<limit lower="-3.1416" upper="3.1416" effort="100" velocity="2.26" />
		</joint>
		<joint name="${prefix}joint2" type="revolute">
			<parent link="link1"/>
			<child link="link2"/>
			<origin xyz="0.4 -0.130 0.445" rpy="0 -1.57 0"/>
			<axis xyz="0 1 0" />
			<limit lower="-0.733" upper="2.269" effort="100" velocity="2.26" />
		</joint>
		<joint name="${prefix}joint3" type="revolute">
			<parent link="link2"/>
			<child link="link3"/>
			<origin xyz="0.75 0.01 0" rpy="0 0 0"/>
			<axis xyz="0 -1 0" />
			<limit lower="-2.967" upper="1.92" effort="100" velocity="2.96" />
		</joint>
		<joint name="${prefix}joint4" type="revolute">
			<parent link="link3"/>
			<child link="link4"/>
			<origin xyz="0.234 0.120 0.250" rpy="0 0 0"/>
			<axis xyz="-1 0 0" />
			<limit lower="-3.1416" upper="3.1416" effort="100" velocity="2.96" />
		</joint>
		<joint name="${prefix}joint5" type="revolute">
			<parent link="link4"/>
			<child link="link5"/>
			<origin xyz="0.578 0 0" rpy="0 0 0"/>
			<axis xyz="0 1 0" />
			<limit lower="-2.147" upper="2.147" effort="100" velocity="3.48" />
		</joint>
		<joint name="${prefix}joint6" type="revolute">
			<parent link="link5"/>
			<child link="link6"/>
			<origin xyz="0.150 0 0" rpy="0 0 0"/>
			<axis xyz="-1 0 0" />
			<limit lower="-3.1416" upper="3.1416" effort="100" velocity="3.48" />
		</joint>
		<!-- end of joint list -->
	</xacro:macro>
</robot>
