<?xml version="1.0" ?>
<!-- =================================================================================== -->
<!-- |    This document was autogenerated by xacro from NM45_teleop_dual.xacro         | -->
<!-- |    EDITING THIS FILE BY HAND IS NOT RECOMMENDED                                 | -->
<!-- =================================================================================== -->
<robot name="Smart_NM45_Dual" xmlns:xacro="http://ros.org/wiki/xacro">
  <link name="base_link">
		</link>
  <link name="link0_1">
    <visual>
      <geometry>
        <mesh filename="package://comau_config/meshes/visual/NM-45_Base.STL"/>
      </geometry>
      <material name="red">
        <color rgba="1 0 0 1"/>
      </material>
    </visual>
    <collision>
      <geometry>
        <mesh filename="package://comau_config/meshes/collision/NM-45_Base_CH.STL"/>
      </geometry>
      <material name="yellow">
        <color rgba="0 1 1 1"/>
      </material>
    </collision>
  </link>
  <link name="link1_1">
    <visual>
      <origin rpy="0 0 0" xyz="0 0 0"/>
      <geometry>
        <mesh filename="package://comau_config/meshes/visual/NM-45_Link1.STL"/>
      </geometry>
      <material name="red">
        <color rgba="1 0 0 1"/>
      </material>
    </visual>
    <collision>
      <origin rpy="0 0 0" xyz="0 0 0"/>
      <geometry>
        <mesh filename="package://comau_config/meshes/collision/NM-45_Link1_CH.STL"/>
      </geometry>
      <material name="yellow"/>
    </collision>
  </link>
  <link name="link2_1">
    <visual>
      <origin rpy="0 0 0" xyz="0 0 0"/>
      <geometry>
        <mesh filename="package://comau_config/meshes/visual/NM-45_Link2.STL"/>
      </geometry>
      <material name="red"/>
    </visual>
    <collision>
      <origin rpy="0 0 0" xyz="0 0 0"/>
      <geometry>
        <mesh filename="package://comau_config/meshes/collision/NM-45_Link2_CH.STL"/>
      </geometry>
      <material name="yellow"/>
    </collision>
  </link>
  <link name="link3_1">
    <visual>
      <origin rpy="0 0 0" xyz="0 0 0"/>
      <geometry>
        <mesh filename="package://comau_config/meshes/visual/NM-45_Link3.STL"/>
      </geometry>
      <material name="red"/>
    </visual>
    <collision>
      <origin rpy="0 0 0" xyz="0 0 0"/>
      <geometry>
        <mesh filename="package://comau_config/meshes/collision/NM-45_Link3_CH.STL"/>
      </geometry>
      <material name="yellow"/>
    </collision>
  </link>
  <link name="link4_1">
    <visual>
      <origin rpy="0 0 0" xyz="0 0 0"/>
      <geometry>
        <mesh filename="package://comau_config/meshes/visual/NM-45_Link4.STL"/>
      </geometry>
      <material name="red"/>
    </visual>
    <collision>
      <origin rpy="0 0 0" xyz="0 0 0"/>
      <geometry>
        <mesh filename="package://comau_config/meshes/collision/NM-45_Link4_CH.STL"/>
      </geometry>
      <material name="yellow"/>
    </collision>
  </link>
  <link name="link5_1">
    <visual>
      <origin rpy="0 0 0" xyz="0 0 0"/>
      <geometry>
        <mesh filename="package://comau_config/meshes/visual/NM-45_Link5.STL"/>
      </geometry>
      <material name="red"/>
    </visual>
    <collision>
      <origin rpy="0 0 0" xyz="0 0 0"/>
      <geometry>
        <mesh filename="package://comau_config/meshes/collision/NM-45_Link5_CH.STL"/>
      </geometry>
      <material name="yellow"/>
    </collision>
  </link>
  <link name="link6_1">
    <visual>
      <origin rpy="0 0 0" xyz="0 0 0"/>
      <geometry>
        <mesh filename="package://comau_config/meshes/visual/NM-45_Link6.STL"/>
      </geometry>
      <material name="red"/>
    </visual>
    <collision>
      <origin rpy="0 0 0" xyz="0 0 0"/>
      <geometry>
        <mesh filename="package://comau_config/meshes/collision/NM-45_Link6_CH.STL"/>
      </geometry>
      <material name="yellow"/>
    </collision>
  </link>
  <link name="link0_2">
    <visual>
      <origin rpy="0 0 0" xyz="0 0 0"/>
      <geometry>
        <mesh filename="package://comau_config/meshes/visual/NM-45_Base.STL"/>
      </geometry>
      <material name="red">
        <color rgba="1 0 0 1"/>
      </material>
    </visual>
    <collision>
      <geometry>
        <mesh filename="package://comau_config/meshes/collision/NM-45_Base_CH.STL"/>
      </geometry>
      <material name="yellow">
        <color rgba="0 1 1 1"/>
      </material>
    </collision>
  </link>
  <link name="link1_2">
    <visual>
      <origin rpy="0 0 0" xyz="0 0 0"/>
      <geometry>
        <mesh filename="package://comau_config/meshes/visual/NM-45_Link1.STL"/>
      </geometry>
      <material name="red">
        <color rgba="1 0 0 1"/>
      </material>
    </visual>
    <collision>
      <origin rpy="0 0 0" xyz="0 0 0"/>
      <geometry>
        <mesh filename="package://comau_config/meshes/collision/NM-45_Link1_CH.STL"/>
      </geometry>
      <material name="yellow"/>
    </collision>
  </link>
  <link name="link2_2">
    <visual>
      <origin rpy="0 0 0" xyz="0 0 0"/>
      <geometry>
        <mesh filename="package://comau_config/meshes/visual/NM-45_Link2.STL"/>
      </geometry>
      <material name="red"/>
    </visual>
    <collision>
      <origin rpy="0 0 0" xyz="0 0 0"/>
      <geometry>
        <mesh filename="package://comau_config/meshes/collision/NM-45_Link2_CH.STL"/>
      </geometry>
      <material name="yellow"/>
    </collision>
  </link>
  <link name="link3_2">
    <visual>
      <origin rpy="0 0 0" xyz="0 0 0"/>
      <geometry>
        <mesh filename="package://comau_config/meshes/visual/NM-45_Link3.STL"/>
      </geometry>
      <material name="red"/>
    </visual>
    <collision>
      <origin rpy="0 0 0" xyz="0 0 0"/>
      <geometry>
        <mesh filename="package://comau_config/meshes/collision/NM-45_Link3_CH.STL"/>
      </geometry>
      <material name="yellow"/>
    </collision>
  </link>
  <link name="link4_2">
    <visual>
      <origin rpy="0 0 0" xyz="0 0 0"/>
      <geometry>
        <mesh filename="package://comau_config/meshes/visual/NM-45_Link4.STL"/>
      </geometry>
      <material name="red"/>
    </visual>
    <collision>
      <origin rpy="0 0 0" xyz="0 0 0"/>
      <geometry>
        <mesh filename="package://comau_config/meshes/collision/NM-45_Link4_CH.STL"/>
      </geometry>
      <material name="yellow"/>
    </collision>
  </link>
  <link name="link5_2">
    <visual>
      <origin rpy="0 0 0" xyz="0 0 0"/>
      <geometry>
        <mesh filename="package://comau_config/meshes/visual/NM-45_Link5.STL"/>
      </geometry>
      <material name="red"/>
    </visual>
    <collision>
      <origin rpy="0 0 0" xyz="0 0 0"/>
      <geometry>
        <mesh filename="package://comau_config/meshes/collision/NM-45_Link5_CH.STL"/>
      </geometry>
      <material name="yellow"/>
    </collision>
  </link>
  <link name="link6_2">
    <visual>
      <origin rpy="0 0 0" xyz="0 0 0"/>
      <geometry>
        <mesh filename="package://comau_config/meshes/visual/NM-45_Link6.STL"/>
      </geometry>
      <material name="red"/>
    </visual>
    <collision>
      <origin rpy="0 0 0" xyz="0 0 0"/>
      <geometry>
        <mesh filename="package://comau_config/meshes/collision/NM-45_Link6_CH.STL"/>
      </geometry>
      <material name="yellow"/>
    </collision>
  </link>
  <joint name="joint0_1" type="fixed">
    <parent link="base_link"/>
    <child link="link0_1"/>
    <origin rpy="0 0 0" xyz="0 0 0"/>
  </joint>
  <joint name="joint1_1" type="revolute">
    <parent link="link0_1"/>
    <child link="link1_1"/>
    <origin rpy="0 0 0" xyz="0 0 0.305"/>
    <axis xyz="0 0 -1"/>
    <limit effort="100" lower="-3.1416" upper="3.1416" velocity="2.26"/>
  </joint>
  <joint name="joint2_1" type="revolute">
    <parent link="link1_1"/>
    <child link="link2_1"/>
    <origin rpy="0 -1.57 0" xyz="0.4 -0.130 0.445"/>
    <axis xyz="0 1 0"/>
    <limit effort="100" lower="-0.733" upper="2.269" velocity="2.26"/>
  </joint>
  <joint name="joint3_1" type="revolute">
    <parent link="link2_1"/>
    <child link="link3_1"/>
    <origin rpy="0 0 0" xyz="0.75 0.01 0"/>
    <axis xyz="0 -1 0"/>
    <limit effort="100" lower="-2.967" upper="1.92" velocity="2.96"/>
  </joint>
  <joint name="joint4_1" type="revolute">
    <parent link="link3_1"/>
    <child link="link4_1"/>
    <origin rpy="0 0 0" xyz="0.234 0.120 0.250"/>
    <axis xyz="-1 0 0"/>
    <limit effort="100" lower="-3.1416" upper="3.1416" velocity="2.96"/>
  </joint>
  <joint name="joint5_1" type="revolute">
    <parent link="link4_1"/>
    <child link="link5_1"/>
    <origin rpy="0 0 0" xyz="0.578 0 0"/>
    <axis xyz="0 1 0"/>
    <limit effort="100" lower="-2.147" upper="2.147" velocity="3.48"/>
  </joint>
  <joint name="joint6_1" type="revolute">
    <parent link="link5_1"/>
    <child link="link6_1"/>
    <origin rpy="0 0 0" xyz="0.150 0 0"/>
    <axis xyz="-1 0 0"/>
    <limit effort="100" lower="-3.1416" upper="3.1416" velocity="3.48"/>
  </joint>
  <joint name="joint0_2" type="fixed">
    <parent link="base_link"/>
    <child link="link0_2"/>
    <origin rpy="0 0 0" xyz="0 -2 0"/>
  </joint>
  <joint name="joint1_2" type="revolute">
    <parent link="link0_2"/>
    <child link="link1_2"/>
    <origin rpy="0 0 0" xyz="0 0 0.305"/>
    <axis xyz="0 0 -1"/>
    <limit effort="100" lower="-3.1416" upper="3.1416" velocity="2.26"/>
  </joint>
  <joint name="joint2_2" type="revolute">
    <parent link="link1_2"/>
    <child link="link2_2"/>
    <origin rpy="0 -1.57 0" xyz="0.4 -0.130 0.445"/>
    <axis xyz="0 1 0"/>
    <limit effort="100" lower="-0.733" upper="2.269" velocity="2.26"/>
  </joint>
  <joint name="joint3_2" type="revolute">
    <parent link="link2_2"/>
    <child link="link3_2"/>
    <origin rpy="0 0 0" xyz="0.75 0.01 0"/>
    <axis xyz="0 -1 0"/>
    <limit effort="100" lower="-2.967" upper="1.92" velocity="2.96"/>
  </joint>
  <joint name="joint4_2" type="revolute">
    <parent link="link3_2"/>
    <child link="link4_2"/>
    <origin rpy="0 0 0" xyz="0.234 0.120 0.250"/>
    <axis xyz="-1 0 0"/>
    <limit effort="100" lower="-3.1416" upper="3.1416" velocity="2.96"/>
  </joint>
  <joint name="joint5_2" type="revolute">
    <parent link="link4_2"/>
    <child link="link5_2"/>
    <origin rpy="0 0 0" xyz="0.578 0 0"/>
    <axis xyz="0 1 0"/>
    <limit effort="100" lower="-2.147" upper="2.147" velocity="3.48"/>
  </joint>
  <joint name="joint6_2" type="revolute">
    <parent link="link5_2"/>
    <child link="link6_2"/>
    <origin rpy="0 0 0" xyz="0.150 0 0"/>
    <axis xyz="-1 0 0"/>
    <limit effort="100" lower="-3.1416" upper="3.1416" velocity="3.48"/>
  </joint>
  <link name="finger_1_link_0">
    <visual>
      <origin rpy="0 0 0" xyz="0.020 0 0"/>
      <geometry>
        <mesh filename="package://robotiq_s_model_visualization/meshes/s-model_articulated/visual/link_0.STL"/>
      </geometry>
      <material name="green">
        <color rgba="0 1 0 1"/>
      </material>
    </visual>
    <collision>
      <origin rpy="0 3.1416 -1.57" xyz="-0.0455 0.0414 0.036"/>
      <geometry>
        <mesh filename="package://robotiq_s_model_visualization/meshes/s-model_articulated/collision/link_0.STL"/>
      </geometry>
      <material name="yellow">
        <color rgba="0 1 1 1"/>
      </material>
    </collision>
  </link>
  <link name="finger_1_link_1">
    <visual>
      <origin rpy="0 0 -0.52" xyz="0.050 -.028 0"/>
      <geometry>
        <mesh filename="package://robotiq_s_model_visualization/meshes/s-model_articulated/visual/link_1.STL"/>
      </geometry>
      <material name="green"/>
    </visual>
    <collision>
      <origin rpy="0 0 -0.52" xyz="0.050 -.028 0"/>
      <geometry>
        <mesh filename="package://robotiq_s_model_visualization/meshes/s-model_articulated/collision/link_1.STL"/>
      </geometry>
      <material name="yellow"/>
    </collision>
  </link>
  <link name="finger_1_link_2">
    <!--
			NOTE: This link has an offset in the z-direction based on the models that were
			used to generate grap-it poses.  With the offset below the model appears visually
			correct, but it is suspect.
			-->
    <visual>
      <origin rpy="0 0 0" xyz="0.039 0 0.0075"/>
      <geometry>
        <mesh filename="package://robotiq_s_model_visualization/meshes/s-model_articulated/visual/link_2.STL"/>
      </geometry>
      <material name="green"/>
    </visual>
    <collision>
      <origin rpy="0 0 0" xyz="0.039 0 0.0075"/>
      <geometry>
        <mesh filename="package://robotiq_s_model_visualization/meshes/s-model_articulated/collision/link_2.STL"/>
      </geometry>
      <material name="yellow"/>
    </collision>
  </link>
  <link name="finger_1_link_3">
    <visual>
      <origin rpy="0 0 0.52" xyz="0 0 0"/>
      <geometry>
        <mesh filename="package://robotiq_s_model_visualization/meshes/s-model_articulated/visual/link_3.STL"/>
      </geometry>
      <material name="green"/>
    </visual>
    <collision>
      <origin rpy="0 0 0.52" xyz="0 0 0"/>
      <geometry>
        <mesh filename="package://robotiq_s_model_visualization/meshes/s-model_articulated/collision/link_3.STL"/>
      </geometry>
      <material name="yellow"/>
    </collision>
  </link>
  <joint name="finger_1_joint_1" type="revolute">
    <parent link="finger_1_link_0"/>
    <child link="finger_1_link_1"/>
    <axis xyz="0 0 1"/>
    <origin rpy="0 0 0" xyz="0.020 0 0"/>
    <limit effort="100" lower="0" upper="3.1416" velocity="100"/>
  </joint>
  <joint name="finger_1_joint_2" type="revolute">
    <parent link="finger_1_link_1"/>
    <child link="finger_1_link_2"/>
    <axis xyz="0 0 1"/>
    <origin rpy="0 0 -0.52" xyz="0.050 -.028 0"/>
    <limit effort="100" lower="0" upper="3.1416" velocity="100"/>
  </joint>
  <joint name="finger_1_joint_3" type="revolute">
    <parent link="finger_1_link_2"/>
    <child link="finger_1_link_3"/>
    <axis xyz="0 0 1"/>
    <origin rpy="0 0 0" xyz="0.039 0 0"/>
    <limit effort="100" lower="0" upper="3.1416" velocity="100"/>
  </joint>
  <link name="finger_2_link_0">
    <visual>
      <origin rpy="0 0 0" xyz="0.020 0 0"/>
      <geometry>
        <mesh filename="package://robotiq_s_model_visualization/meshes/s-model_articulated/visual/link_0.STL"/>
      </geometry>
      <material name="green">
        <color rgba="0 1 0 1"/>
      </material>
    </visual>
    <collision>
      <origin rpy="0 3.1416 -1.57" xyz="-0.0455 0.0414 0.036"/>
      <geometry>
        <mesh filename="package://robotiq_s_model_visualization/meshes/s-model_articulated/collision/link_0.STL"/>
      </geometry>
      <material name="yellow">
        <color rgba="0 1 1 1"/>
      </material>
    </collision>
  </link>
  <link name="finger_2_link_1">
    <visual>
      <origin rpy="0 0 -0.52" xyz="0.050 -.028 0"/>
      <geometry>
        <mesh filename="package://robotiq_s_model_visualization/meshes/s-model_articulated/visual/link_1.STL"/>
      </geometry>
      <material name="green"/>
    </visual>
    <collision>
      <origin rpy="0 0 -0.52" xyz="0.050 -.028 0"/>
      <geometry>
        <mesh filename="package://robotiq_s_model_visualization/meshes/s-model_articulated/collision/link_1.STL"/>
      </geometry>
      <material name="yellow"/>
    </collision>
  </link>
  <link name="finger_2_link_2">
    <!--
			NOTE: This link has an offset in the z-direction based on the models that were
			used to generate grap-it poses.  With the offset below the model appears visually
			correct, but it is suspect.
			-->
    <visual>
      <origin rpy="0 0 0" xyz="0.039 0 0.0075"/>
      <geometry>
        <mesh filename="package://robotiq_s_model_visualization/meshes/s-model_articulated/visual/link_2.STL"/>
      </geometry>
      <material name="green"/>
    </visual>
    <collision>
      <origin rpy="0 0 0" xyz="0.039 0 0.0075"/>
      <geometry>
        <mesh filename="package://robotiq_s_model_visualization/meshes/s-model_articulated/collision/link_2.STL"/>
      </geometry>
      <material name="yellow"/>
    </collision>
  </link>
  <link name="finger_2_link_3">
    <visual>
      <origin rpy="0 0 0.52" xyz="0 0 0"/>
      <geometry>
        <mesh filename="package://robotiq_s_model_visualization/meshes/s-model_articulated/visual/link_3.STL"/>
      </geometry>
      <material name="green"/>
    </visual>
    <collision>
      <origin rpy="0 0 0.52" xyz="0 0 0"/>
      <geometry>
        <mesh filename="package://robotiq_s_model_visualization/meshes/s-model_articulated/collision/link_3.STL"/>
      </geometry>
      <material name="yellow"/>
    </collision>
  </link>
  <joint name="finger_2_joint_1" type="revolute">
    <parent link="finger_2_link_0"/>
    <child link="finger_2_link_1"/>
    <axis xyz="0 0 1"/>
    <origin rpy="0 0 0" xyz="0.020 0 0"/>
    <limit effort="100" lower="0" upper="3.1416" velocity="100"/>
  </joint>
  <joint name="finger_2_joint_2" type="revolute">
    <parent link="finger_2_link_1"/>
    <child link="finger_2_link_2"/>
    <axis xyz="0 0 1"/>
    <origin rpy="0 0 -0.52" xyz="0.050 -.028 0"/>
    <limit effort="100" lower="0" upper="3.1416" velocity="100"/>
  </joint>
  <joint name="finger_2_joint_3" type="revolute">
    <parent link="finger_2_link_2"/>
    <child link="finger_2_link_3"/>
    <axis xyz="0 0 1"/>
    <origin rpy="0 0 0" xyz="0.039 0 0"/>
    <limit effort="100" lower="0" upper="3.1416" velocity="100"/>
  </joint>
  <link name="finger_middle_link_0">
    <visual>
      <origin rpy="0 0 0" xyz="0.020 0 0"/>
      <geometry>
        <mesh filename="package://robotiq_s_model_visualization/meshes/s-model_articulated/visual/link_0.STL"/>
      </geometry>
      <material name="green">
        <color rgba="0 1 0 1"/>
      </material>
    </visual>
    <collision>
      <origin rpy="0 3.1416 -1.57" xyz="-0.0455 0.0414 0.036"/>
      <geometry>
        <mesh filename="package://robotiq_s_model_visualization/meshes/s-model_articulated/collision/link_0.STL"/>
      </geometry>
      <material name="yellow">
        <color rgba="0 1 1 1"/>
      </material>
    </collision>
  </link>
  <link name="finger_middle_link_1">
    <visual>
      <origin rpy="0 0 -0.52" xyz="0.050 -.028 0"/>
      <geometry>
        <mesh filename="package://robotiq_s_model_visualization/meshes/s-model_articulated/visual/link_1.STL"/>
      </geometry>
      <material name="green"/>
    </visual>
    <collision>
      <origin rpy="0 0 -0.52" xyz="0.050 -.028 0"/>
      <geometry>
        <mesh filename="package://robotiq_s_model_visualization/meshes/s-model_articulated/collision/link_1.STL"/>
      </geometry>
      <material name="yellow"/>
    </collision>
  </link>
  <link name="finger_middle_link_2">
    <!--
			NOTE: This link has an offset in the z-direction based on the models that were
			used to generate grap-it poses.  With the offset below the model appears visually
			correct, but it is suspect.
			-->
    <visual>
      <origin rpy="0 0 0" xyz="0.039 0 0.0075"/>
      <geometry>
        <mesh filename="package://robotiq_s_model_visualization/meshes/s-model_articulated/visual/link_2.STL"/>
      </geometry>
      <material name="green"/>
    </visual>
    <collision>
      <origin rpy="0 0 0" xyz="0.039 0 0.0075"/>
      <geometry>
        <mesh filename="package://robotiq_s_model_visualization/meshes/s-model_articulated/collision/link_2.STL"/>
      </geometry>
      <material name="yellow"/>
    </collision>
  </link>
  <link name="finger_middle_link_3">
    <visual>
      <origin rpy="0 0 0.52" xyz="0 0 0"/>
      <geometry>
        <mesh filename="package://robotiq_s_model_visualization/meshes/s-model_articulated/visual/link_3.STL"/>
      </geometry>
      <material name="green"/>
    </visual>
    <collision>
      <origin rpy="0 0 0.52" xyz="0 0 0"/>
      <geometry>
        <mesh filename="package://robotiq_s_model_visualization/meshes/s-model_articulated/collision/link_3.STL"/>
      </geometry>
      <material name="yellow"/>
    </collision>
  </link>
  <joint name="finger_middle_joint_1" type="revolute">
    <parent link="finger_middle_link_0"/>
    <child link="finger_middle_link_1"/>
    <axis xyz="0 0 1"/>
    <origin rpy="0 0 0" xyz="0.020 0 0"/>
    <limit effort="100" lower="0" upper="3.1416" velocity="100"/>
  </joint>
  <joint name="finger_middle_joint_2" type="revolute">
    <parent link="finger_middle_link_1"/>
    <child link="finger_middle_link_2"/>
    <axis xyz="0 0 1"/>
    <origin rpy="0 0 -0.52" xyz="0.050 -.028 0"/>
    <limit effort="100" lower="0" upper="3.1416" velocity="100"/>
  </joint>
  <joint name="finger_middle_joint_3" type="revolute">
    <parent link="finger_middle_link_2"/>
    <child link="finger_middle_link_3"/>
    <axis xyz="0 0 1"/>
    <origin rpy="0 0 0" xyz="0.039 0 0"/>
    <limit effort="100" lower="0" upper="3.1416" velocity="100"/>
  </joint>
  <link name="palm">
    <visual>
      <geometry>
        <mesh filename="package://robotiq_s_model_visualization/meshes/s-model_articulated/visual/palm.STL"/>
      </geometry>
      <material name="green">
        <color rgba="0 1 0 1"/>
      </material>
    </visual>
    <collision>
      <geometry>
        <mesh filename="package://robotiq_s_model_visualization/meshes/s-model_articulated/collision/palm.STL"/>
      </geometry>
      <material name="yellow">
        <color rgba="0 1 1 1"/>
      </material>
    </collision>
  </link>
  <joint name="palm_finger_1_joint" type="revolute">
    <parent link="palm"/>
    <child link="finger_1_link_0"/>
    <axis xyz="0 1 0"/>
    <origin rpy="0 3.1416 -1.57" xyz="-0.0455 0.0214 0.036"/>
    <limit effort="100" lower="-0.16" upper="0.25" velocity="100"/>
  </joint>
  <joint name="palm_finger_2_joint" type="revolute">
    <parent link="palm"/>
    <child link="finger_2_link_0"/>
    <axis xyz="0 1 0"/>
    <origin rpy="0 3.1416 -1.57" xyz="-0.0455 0.0214 -0.036"/>
    <limit effort="100" lower="-0.25" upper="0.16" velocity="100"/>
  </joint>
  <joint name="palm_finger_middle_joint" type="fixed">
    <parent link="palm"/>
    <child link="finger_middle_link_0"/>
    <axis xyz="0 0 1"/>
    <origin rpy="0 0 1.57" xyz="0.0455 0.0214 0"/>
  </joint>
  <!-- link list -->
  <link name="eff_stack_1">
    <visual>
      <geometry>
        <mesh filename="package://comau_config/meshes/visual/Effector_stack.STL"/>
      </geometry>
      <material name="orange">
        <color rgba="1 0.5 0 1"/>
      </material>
    </visual>
    <collision>
      <geometry>
        <mesh filename="package://comau_config/meshes/collision/Effector_stack_CH.STL"/>
      </geometry>
      <material name="yellow">
        <color rgba="0 1 1 1"/>
      </material>
    </collision>
  </link>
  <link name="eff_stack_2">
    <visual>
      <geometry>
        <mesh filename="package://comau_config/meshes/visual/Effector_stack.STL"/>
      </geometry>
      <material name="orange">
        <color rgba="1 0.5 0 1"/>
      </material>
    </visual>
    <collision>
      <geometry>
        <mesh filename="package://comau_config/meshes/collision/Effector_stack_CH.STL"/>
      </geometry>
      <material name="yellow">
        <color rgba="0 1 1 1"/>
      </material>
    </collision>
  </link>
  <!-- end link list -->
  <!-- joint list -->
  <joint name="flange2stack_1" type="fixed">
    <parent link="link6_1"/>
    <child link="eff_stack_1"/>
    <origin rpy="0 1.57 0" xyz="0.025 0 0"/>
  </joint>
  <joint name="stack2hand_1" type="fixed">
    <parent link="eff_stack_1"/>
    <child link="palm"/>
    <origin rpy="1.57 0 0" xyz="0 0 0.2123"/>
  </joint>
  <joint name="flange2stack_2" type="fixed">
    <parent link="link6_2"/>
    <child link="eff_stack_2"/>
    <origin rpy="0 1.57 0" xyz="0.025 0 0"/>
  </joint>
  <!-- end of joint list -->
</robot>

