<robot xmlns:xacro="http://ros.org/wiki/xacro">
	<xacro:macro name="comau_nm45" params="prefix">

		<!-- ros_control plugin -->
  		<gazebo>
    		  <plugin name="gazebo_ros_control" filename="libgazebo_ros_control.so">
      		    <robotNamespace>/comau_nm45</robotNamespace>		 
    		  </plugin>
  		</gazebo>
		
		<!-- link list -->
		<!-- Used for fixing robot to Gazebo 'base_link' -->
  		<link name="world"/>

		<link name="${prefix}base_link">
			<visual>
				<geometry>
					<mesh filename="package://comau_nm45_description/meshes/visual/NM-45_Base.STL" />
				</geometry>
				<material name="red">
					<color rgba="1 0 0 1"/>
				</material>
			</visual>
			<collision>
				<geometry>
					<mesh filename="package://comau_nm45_description/meshes/collision/NM-45_Base_CH.STL" />
				</geometry>
				<material name="yellow">
					<color rgba="0 1 1 1"/>
				</material>
			</collision>
			<inertial>
      				<origin xyz="-0.039 0 0.137" rpy="0 0 0"/>
     				<mass value="687.65815"/>
      				<inertia 
        			  ixx="21.60311" ixy="-0.25255" ixz="0.78936" 
        			  iyy="31.75235" iyz="-0.34612" 
        			  izz="45.97675"/>
    			</inertial>
		</link>
		<link name="${prefix}link1">
			<visual>
				<origin rpy="0 0 0" xyz="0 0 0.08495"/>
				<geometry>
					<mesh filename="package://comau_nm45_description/meshes/visual/NM-45_Link1.STL"/>
				</geometry>
				<material name="red">
					<color rgba="1 0 0 1"/>
				</material>
			</visual>
			<collision>
				<origin rpy="0 0 0" xyz="0 0 0.08495"/>
				<geometry>
					<mesh filename="package://comau_nm45_description/meshes/collision/NM-45_Link1_CH.STL" />
				</geometry>
				<material name="yellow"/>
			</collision>
			<inertial>
      				<origin xyz="0.15159 0 0.31076" rpy="0 0 0"/>
				<!--origin xyz="0 0 0" rpy="0 0 0"/-->
     				<mass value="704.18892"/>
      				<inertia 
        			  ixx="27.07108" ixy="-2.64292" ixz="12.09446" 
        			  iyy="42.98623" iyz="-1.06182" 
        			  izz="37.37951"/>
    			</inertial>
		</link>
		<link name="${prefix}link2">
			<visual>
				<origin rpy="-1.5709 0 0" xyz="0 0 0.13"/>
				<geometry>
					<mesh filename="package://comau_nm45_description/meshes/visual/NM-45_Link2.STL"/>
				</geometry>
				<material name="red"/>
			</visual>
			<collision>
				<origin rpy="-1.5709 0 0" xyz="0 0 0.13"/>
				<geometry>
					<mesh filename="package://comau_nm45_description/meshes/collision/NM-45_Link2_CH.STL"/>
				</geometry>
				<material name="yellow"/>
			</collision>
			<inertial>
      				<!--origin xyz="0.3626 0.01795 -0.21355" rpy="0 0 0"/-->
				<origin xyz="0.3626 -0.01795 0.21355" rpy="0 0 0"/>
     				<mass value="132.82859"/>
      				<inertia 
        			  ixx="1.09188" ixy="0.03363" ixz="0.12496" 
        			  iyy="9.44429" iyz="0.06296" 
        			  izz="19.4647"/>
    			</inertial>
		</link>
		<link name="${prefix}link3">
			<visual>
				<origin rpy="-1.5709 0 0" xyz="0 0 0.12"/>
				<geometry>
					<mesh filename="package://comau_nm45_description/meshes/visual/NM-45_Link3.STL"/>
				</geometry>
				<material name="red"/>
			</visual>
			<collision>
				<origin rpy="-1.5709 0 0" xyz="0 0 0.12"/>
				<geometry>
					<mesh filename="package://comau_nm45_description/meshes/collision/NM-45_Link3_CH.STL"/>
				</geometry>
				<material name="yellow"/>
			</collision>
			<inertial>
      				<origin xyz="-0.07988 0.1602 -0.0436" rpy="0 0 0"/>
     				<mass value="335.63154"/>
      				<inertia 
        			  ixx="6.26957" ixy="-1.11794" ixz="1.088130" 
        			  iyy="10.78805" iyz="-0.23637" 
        			  izz="25.5045"/>
    			</inertial>
		</link>
		<link name="${prefix}link4">
			<visual>
				<origin rpy="-1.5709 -1.5709 0" xyz="0 0 0"/>
				<geometry>
					<mesh filename="package://comau_nm45_description/meshes/visual/NM-45_Link4.STL"/>
				</geometry>
				<material name="red"/>
			</visual>
			<collision>
				<origin rpy="-1.5709 -1.5709 0" xyz="0 0 0"/>
				<geometry>
					<mesh filename="package://comau_nm45_description/meshes/collision/NM-45_Link4_CH.STL"/>
				</geometry>
				<material name="yellow"/>
			</collision>
			<inertial>
      				<origin xyz="-0.01981 0 0.34863" rpy="0 0 0"/>
     				<mass value="40.81696"/>
      				<inertia 
        			  ixx="3.53002" ixy="0" ixz="0.16885" 
        			  iyy="1.79464" iyz="0.0" 
        			  izz="0.09717"/>
    			</inertial>
		</link>
		<link name="${prefix}link5">
			<visual>
				<origin rpy="-1.5709 0 0" xyz="0 0 0"/>
				<geometry>
					<mesh filename="package://comau_nm45_description/meshes/visual/NM-45_Link5.STL"/>
				</geometry>
				<material name="red"/>
			</visual>
			<collision>
				<origin rpy="0 0 0" xyz="0 0 0"/>
				<geometry>
					<mesh filename="package://comau_nm45_description/meshes/collision/NM-45_Link5_CH.STL"/>
				</geometry>
				<material name="yellow"/>
			</collision>
			<inertial>
      				<origin xyz="0.06264 0 0" rpy="0 0 0"/>
     				<mass value="18.36813"/>
      				<inertia 
        			  ixx="0.1138" ixy="0.0" ixz="0.604" 
        			  iyy="0.15699" iyz="0.0" 
        			  izz="0.15854"/>
    			</inertial>
		</link>
		<!-- end of link list -->
		<!-- joint list -->
		<joint name="fixed" type="fixed">
    			<parent link="world"/>
    			<child link="base_link"/>
  		</joint>
		<joint name="${prefix}joint1" type="revolute">
			<parent link="base_link"/>
			<child link="link1"/>
			<origin xyz="0 0 0.22005" rpy="0 0 0"/>
			<axis xyz="0 0 -1" />
			<limit lower="-3.1416" upper="3.1415" effort="100" velocity="2.26" />
		</joint>
		<joint name="${prefix}joint2" type="revolute">
			<parent link="link1"/>
			<child link="link2"/>
			<origin xyz="0.4 0.0 0.530" rpy="1.5708 -1.5708 0"/>
			<axis xyz="0 0 -1" />
			<limit lower="-0.733" upper="2.269" effort="10000" velocity="2.26" />
		</joint>
		<joint name="${prefix}joint3" type="revolute">
			<parent link="link2"/>
			<child link="link3"/>
			<origin xyz="0.75 0.0 0" rpy="0 0 -1.5708"/>
			<axis xyz="0 0 1" />
			<limit lower="-2.967" upper="1.92" effort="1000" velocity="2.96" />
		</joint>
		<joint name="${prefix}joint4" type="revolute">
			<parent link="link3"/>
			<child link="link4"/>
			<origin xyz="0.255 0.25 0" rpy="0 1.5708 0"/>
			<axis xyz="0 0 -1" />
			<limit lower="-3.1416" upper="3.1415" effort="1000" velocity="2.96" />
		</joint>
		<joint name="${prefix}joint5" type="revolute">
			<parent link="link4"/>
			<child link="link5"/>
			<origin xyz="0 0 0.5574" rpy="0 -1.5708 0"/>
			<axis xyz="0 0 -1" />
			<limit lower="-2.147" upper="2.147" effort="100" velocity="3.48" />
		</joint>
		<!-- end of joint list -->

		<!-- transmission list -->
		<transmission name="tran1">
    		  <type>transmission_interface/SimpleTransmission</type>
    		  <joint name="${prefix}joint1"/>
    		  <actuator name="motor1">
      		    <hardwareInterface>EffortJointInterface</hardwareInterface>
      		    <mechanicalReduction>139.03</mechanicalReduction>
    		  </actuator>
 		</transmission>

  		<transmission name="tran2">
    		  <type>transmission_interface/SimpleTransmission</type>
    		  <joint name="${prefix}joint2"/>
    		  <actuator name="motor2">
      		    <hardwareInterface>EffortJointInterface</hardwareInterface>
      		    <mechanicalReduction>163.5</mechanicalReduction>
    		  </actuator>
  		</transmission>

		<transmission name="tran3">
    		  <type>transmission_interface/SimpleTransmission</type>
    		  <joint name="${prefix}joint3"/>
    		  <actuator name="motor3">
      		    <hardwareInterface>EffortJointInterface</hardwareInterface>
      		    <mechanicalReduction>159.261</mechanicalReduction>
    		  </actuator>
  		</transmission>

		<transmission name="tran4">
    		  <type>transmission_interface/SimpleTransmission</type>
    		  <joint name="${prefix}joint4"/>
    		  <actuator name="motor4">
      		    <hardwareInterface>EffortJointInterface</hardwareInterface>
      		    <mechanicalReduction>65.6118</mechanicalReduction>
    		  </actuator>
  		</transmission>

		<transmission name="tran5">
    		  <type>transmission_interface/SimpleTransmission</type>
    		  <joint name="${prefix}joint5"/>
    		  <actuator name="motor5">
      		    <hardwareInterface>EffortJointInterface</hardwareInterface>
      		    <mechanicalReduction>84.1923</mechanicalReduction>
    		  </actuator>
  		</transmission>

		<!-- end transmission list -->

	</xacro:macro>
</robot>
