<robot xmlns:xacro="http://ros.org/wiki/xacro">
	<xacro:macro name="comau_nm45" params="prefix">

		<!-- ros_control plugin -->
  		<gazebo>
    		  <plugin name="gazebo_ros_control" filename="libgazebo_ros_control.so">
      		    <robotNamespace>/comau_nm45</robotNamespace>		 
    		  </plugin>
  		</gazebo>
		
		<!-- link list -->
		<!-- Used for fixing robot to Gazebo 'base_link' -->
  		<link name="world"/>

		<link name="${prefix}base_link">
			<visual>
				<geometry>
					<mesh filename="package://comau_nm45_description/meshes/visual/NM-45_Base.STL" />
				</geometry>
				<material name="red">
					<color rgba="1 0 0 1"/>
				</material>
			</visual>
			<collision>
				<geometry>
					<mesh filename="package://comau_nm45_description/meshes/collision/NM-45_Base_CH.STL" />
				</geometry>
				<material name="yellow">
					<color rgba="0 1 1 1"/>
				</material>
			</collision>
			<inertial>
      				<origin xyz="-0.039 0 0.137" rpy="0 0 0"/>
     				<mass value="687.65815"/>
      				<inertia 
        			  ixx="21.60311" ixy="-0.25255" ixz="0.78936" 
        			  iyy="31.75235" iyz="-0.34612" 
        			  izz="45.97675"/>
    			</inertial>
		</link>
		<link name="${prefix}link1">
			<visual>
				<origin rpy="0 0 0" xyz="0 0 0.08495"/>
				<geometry>
					<mesh filename="package://comau_nm45_description/meshes/visual/NM-45_Link1.STL"/>
				</geometry>
				<material name="red">
					<color rgba="1 0 0 1"/>
				</material>
			</visual>
			<collision>
				<origin rpy="0 0 0" xyz="0 0 0.08495"/>
				<geometry>
					<mesh filename="package://comau_nm45_description/meshes/collision/NM-45_Link1_CH.STL" />
				</geometry>
				<material name="yellow"/>
			</collision>
			<inertial>
      				<origin xyz="0.15159 0 0.31076" rpy="0 0 0"/>
				<!--origin xyz="0 0 0" rpy="0 0 0"/-->
     				<mass value="704.18892"/>
      				<inertia 
        			  ixx="27.07108" ixy="-2.64292" ixz="12.09446" 
        			  iyy="42.98623" iyz="-1.06182" 
        			  izz="37.37951"/>
    			</inertial>
		</link>
		
		<!-- end of link list -->
		<!-- joint list -->
		<joint name="fixed" type="fixed">
    			<parent link="world"/>
    			<child link="base_link"/>
  		</joint>
		<joint name="${prefix}joint1" type="revolute">
		<!-- joint name="${prefix}joint1" type="continuous"-->
			<parent link="base_link"/>
			<child link="link1"/>
			<origin xyz="0 0 0.22005" rpy="0 0 0"/>
			<axis xyz="0 0 -1" />
			<limit lower="-3.1416" upper="3.14159" effort="100" velocity="2.26" />
			<!-- limit lower="-2" upper="2" effort="100" velocity="2.26" /-->
		</joint>
		
		<!-- end of joint list -->

		<!-- transmission list -->
		<transmission name="tran1">
    		  <type>transmission_interface/SimpleTransmission</type>
    		  <joint name="joint1"/>
    		  <actuator name="motor1">
      		    <hardwareInterface>EffortJointInterface</hardwareInterface>
      		    <mechanicalReduction>1</mechanicalReduction>
    		  </actuator>
 		</transmission>
		<!-- end transmission list -->

	</xacro:macro>
</robot>
